Workbook

Sheet Trades
A1: ID | B1: Date | C1: Time ET | D1: Time IL | E1: Sys | F1: Pattern | G1: Dir | H1: Day Type | I1: Entry | J1: Stop initial | K1: Stop final | L1: Risk pts | M1: T1 anchor | N1: T1 R | O1: T2 anchor | P1: T3 | Q1: T1 hit | R1: BE moved | S1: T2 hit | T1: MFE pts | U1: MAE pts | V1: Captured pts | W1: Exit reason | X1: Outcome | Y1: PnL $ | Z1: True R | AA1: Bars | AB1: Flags
A2: 10 | B2: 2026-06-05 | C2: 14:15 | D2: 21:15 | E2: 2 | F2: BEAR_FLAG_SHORT | G2: SHORT | H2: Variation | I2: 7444 | J2: 7457.0312 | K2: 7443.75 | L2: 13 | M2: 7428.75 | N2: 1.17 | O2: 7413.5 | P2: 0 | Q2: YES | R2: YES | S2: YES | T2: 83 | U2: 25.5 | V2: 15.33 | W2: STOP_HIT | X2: WIN | Y2: 230 | Z2: 1.18 | AA2: 12
A3: 12 | B3: 2026-06-05 | C3: 14:15 | D3: 21:15 | E3: 4 | F3: HTLB | G3: SHORT | H3: Variation | I3: 7443.75 | J3: 7447.25 | K3: 7443.5 | L3: 3.5 | M3: 7440.25 | N3: 1 | O3: 7436.75 | P3: 0 | Q3: YES | R3: YES | V3: 1.33 | W3: STOP_HIT | X3: WIN | Y3: 20 | Z3: 0.38 | AA3: 0
A4: 13 | B4: 2026-06-05 | C4: 15:05 | D4: 22:05 | E4: 2 | F4: REACTIVE_SHORT | G4: SHORT | H4: Variation | I4: 7414.25 | J4: 7418 | K4: 7414 | L4: 3.8 | M4: 7410.5 | N4: 1 | O4: 7404.875 | P4: 0 | Q4: YES | R4: YES | S4: YES | T4: 53.25 | U4: 0 | V4: 4.46 | W4: STOP_HIT | X4: WIN | Y4: 66.88 | Z4: 1.19 | AA4: 3
A5: 20 | B5: 2026-06-09 | C5: 09:50 | D5: 16:50 | E5: 4 | F5: HTLB | G5: SHORT | H5: UNKNOWN | I5: 7489.25 | J5: 7491.75 | K5: 7489 | L5: 2.5 | M5: 7485.75 | N5: 1.4 | O5: 7482.25 | Q5: YES | R5: YES | S5: YES | T5: 127 | U5: 0 | V5: 38.83 | W5: TIME_STOP | X5: WIN | Y5: 582.5 | Z5: 15.53 | AA5: 18
A6: 22 | B6: 2026-06-09 | C6: 12:00 | D6: 19:00 | E6: 2 | F6: BEAR_FLAG_SHORT | G6: SHORT | H6: Variation | I6: 7313.5 | J6: 7349.75 | K6: 7349.75 | L6: 36.2 | M6: 7259.375 | N6: 1.49 | O6: 7205.25 | T6: 39 | U6: 5.5 | V6: 0 | W6: manual | X6: BE | Y6: 0 | Z6: 0 | AA6: 5 | AB6: RISK 36pt
A7: 24 | B7: 2026-06-10 | C7: 11:09 | D7: 18:09 | E7: 4 | F7: HFE | G7: LONG | H7: UNKNOWN | I7: 7338.5 | J7: 7337.5 | K7: 7337.5 | L7: 1 | M7: 7341.5 | N7: 3 | T7: 2.5 | U7: 11.75 | V7: -1 | W7: STOP_HIT | X7: LOSS | Y7: -15 | Z7: -1 | AA7: 1
A8: 26 | B8: 2026-06-10 | C8: 11:10 | D8: 18:10 | E8: 4 | F8: HFE | G8: LONG | H8: Normal | I8: 7339.25 | J8: 7337.25 | K8: 7337.25 | L8: 2 | M8: 7342.25 | N8: 1.5 | T8: 0 | U8: 23.75 | V8: -2 | W8: STOP_HIT | X8: LOSS | Y8: -30 | Z8: -1 | AA8: 1
A9: 27 | B9: 2026-06-10 | C9: 11:15 | D9: 18:15 | E9: 4 | F9: HFE | G9: LONG | H9: Normal | I9: 7327.5 | J9: 7325.75 | K9: 7325.75 | L9: 1.8 | M9: 7330.5 | N9: 1.71 | T9: 16.75 | U9: 6.75 | V9: -1.75 | W9: STOP_HIT | X9: LOSS | Y9: -26.25 | Z9: -1 | AA9: 1
A10: 28 | B10: 2026-06-11 | C10: 09:30 | D10: 16:30 | E10: 4 | F10: ZLR | G10: SHORT | H10: UNKNOWN | I10: 7306.25 | J10: 7313.5 | K10: 7306 | L10: 7.2 | M10: 7300.81 | N10: 0.75 | Q10: YES | R10: YES | T10: 23.25 | U10: 11.5 | V10: 1.98 | W10: STOP_HIT | X10: WIN | Y10: 29.7 | Z10: 0.27 | AA10: 3
A11: 30 | B11: 2026-06-11 | C11: 09:50 | D11: 16:50 | E11: 4 | F11: TLB | G11: LONG | H11: UNKNOWN | I11: 7306.25 | J11: 7282.25 | K11: 7306.5 | L11: 24 | M11: 7315.85 | N11: 0.4 | Q11: YES | R11: YES | T11: 29.5 | U11: 9 | V11: 3.37 | W11: STOP_HIT | X11: WIN | Y11: 50.5 | Z11: 0.14 | AA11: 4
A12: 31 | B12: 2026-06-11 | C12: 10:10 | D12: 17:10 | E12: 4 | F12: TLB | G12: SHORT | H12: Trend_Normal | I12: 7320.75 | J12: 7336.5 | K12: 7320.5 | L12: 15.8 | M12: 7312.88 | N12: 0.5 | Q12: YES | R12: YES | T12: 57.75 | U12: 0 | V12: 13.46 | W12: TIME_STOP | X12: WIN | Y12: 201.85 | Z12: 0.85 | AA12: 18
A13: 32 | B13: 2026-06-11 | C13: 10:15 | D13: 17:15 | E13: 4 | F13: TLB | G13: SHORT | H13: Trend_Normal | I13: 7297.5 | J13: 7336.5 | K13: 7297.25 | L13: 39 | M13: 7281.9 | N13: 0.4 | Q13: YES | R13: YES | T13: 34.5 | U13: 22.75 | V13: 5.37 | W13: STOP_HIT | X13: WIN | Y13: 80.5 | Z13: 0.14 | AA13: 11 | AB13: RISK 39pt
A14: 33 | B14: 2026-06-11 | C14: 10:15 | D14: 17:15 | E14: 2 | F14: REACTIVE_SHORT | G14: SHORT | H14: Trend_Normal | I14: 7297.75 | J14: 7331.25 | K14: 7297.5 | L14: 33.5 | M14: 7284.35 | N14: 0.4 | O14: 7230.75 | Q14: YES | R14: YES | T14: 34.75 | U14: 22.5 | V14: 4.63 | W14: STOP_HIT | X14: WIN | Y14: 69.5 | Z14: 0.14 | AA14: 11 | AB14: RISK 34pt
A15: 34 | B15: 2026-06-11 | C15: 10:20 | D15: 17:20 | E15: 4 | F15: TLB | G15: SHORT | H15: Trend_Normal | I15: 7290 | J15: 7336.5 | K15: 7289.75 | L15: 46.5 | M15: 7271.4 | N15: 0.4 | Q15: YES | R15: YES | T15: 19.75 | U15: 30.25 | V15: 6.37 | W15: STOP_HIT | X15: WIN | Y15: 95.5 | Z15: 0.14 | AA15: 7 | AB15: RISK 46pt
A16: 35 | B16: 2026-06-11 | C16: 10:30 | D16: 17:30 | E16: 4 | F16: ZLR | G16: LONG | H16: Trend_Normal | I16: 7308.5 | J16: 7288.25 | K16: 7308.75 | L16: 20.2 | M16: 7316.6 | N16: 0.4 | Q16: YES | R16: YES | T16: 11.75 | U16: 7.75 | V16: 2.87 | W16: STOP_HIT | X16: WIN | Y16: 43 | Z16: 0.14 | AA16: 1
A17: 36 | B17: 2026-06-11 | C17: 10:35 | D17: 17:35 | E17: 4 | F17: ZLR | G17: SHORT | H17: Trend_Normal | I17: 7301.25 | J17: 7318.25 | K17: 7318.25 | L17: 17 | M17: 7292.75 | N17: 0.5 | T17: 0 | U17: 17.25 | V17: -17 | W17: STOP_HIT | X17: LOSS | Y17: -255 | Z17: -1 | AA17: 1
A18: 37 | B18: 2026-06-11 | C18: 10:50 | D18: 17:50 | E18: 4 | F18: ZLR | G18: SHORT | H18: Trend_Normal | I18: 7300.5 | J18: 7321 | K18: 7300.25 | L18: 20.5 | M18: 7292.3 | N18: 0.4 | Q18: YES | R18: YES | T18: 37.5 | U18: 3.25 | V18: 2.9 | W18: STOP_HIT | X18: WIN | Y18: 43.5 | Z18: 0.14 | AA18: 5
A19: 38 | B19: 2026-06-11 | C19: 11:10 | D19: 18:10 | E19: 4 | F19: TLB | G19: LONG | H19: Variation | I19: 7286.25 | J19: 7262.25 | K19: 7286.5 | L19: 24 | M19: 7295.85 | N19: 0.4 | Q19: YES | R19: YES | T19: 17.5 | U19: 0 | V19: 3.37 | W19: STOP_HIT | X19: WIN | Y19: 50.5 | Z19: 0.14 | AA19: 1
A20: 39 | B20: 2026-06-11 | C20: 11:15 | D20: 18:15 | E20: 4 | F20: TLB | G20: LONG | H20: Variation | I20: 7293 | J20: 7262.25 | K20: 7293.25 | L20: 30.8 | M20: 7305.3 | N20: 0.4 | Q20: YES | R20: YES | T20: 14 | U20: 2.25 | V20: 4.27 | W20: STOP_HIT | X20: WIN | Y20: 64 | Z20: 0.14 | AA20: 1 | AB20: RISK 31pt
A21: 40 | B21: 2026-06-11 | C21: 11:30 | D21: 18:30 | E21: 4 | F21: ZLR | G21: SHORT | H21: Variation | I21: 7291.75 | J21: 7307.75 | K21: 7307.75 | L21: 16 | M21: 7283.75 | N21: 0.5 | T21: 0 | U21: 17 | V21: -16 | W21: STOP_HIT | X21: LOSS | Y21: -240 | Z21: -1 | AA21: 1
A22: 41 | B22: 2026-06-11 | C22: 11:40 | D22: 18:40 | E22: 4 | F22: GHOST | G22: LONG | H22: Variation | I22: 7304.5 | J22: 7262.25 | K22: 7304.75 | L22: 42.2 | M22: 7307.81 | N22: 0.08 | Q22: YES | R22: YES | T22: 5.5 | U22: 17 | V22: 1.27 | W22: STOP_HIT | X22: WIN | Y22: 19.05 | Z22: 0.03 | AA22: 4 | AB22: RISK 42pt
A23: 42 | B23: 2026-06-11 | C23: 11:55 | D23: 18:55 | E23: 4 | F23: ZLR | G23: SHORT | H23: Variation | I23: 7291.75 | J23: 7315 | K23: 7315 | L23: 23.2 | M23: 7282.45 | N23: 0.4 | T23: 0 | U23: 29.25 | V23: -23.25 | W23: STOP_HIT | X23: LOSS | Y23: -348.75 | Z23: -1 | AA23: 3
A24: 43 | B24: 2026-06-11 | C24: 12:15 | D24: 19:15 | E24: 2 | F24: REACTIVE_LONG | G24: LONG | H24: Variation | I24: 7318 | J24: 7295.5 | K24: 7295.5 | L24: 22.5 | M24: 7327 | N24: 0.4 | O24: 7363 | T24: 1.75 | U24: 24.75 | V24: -22.5 | W24: STOP_HIT | X24: LOSS | Y24: -337.5 | Z24: -1 | AA24: 3
A25: 44 | B25: 2026-06-11 | C25: 12:25 | D25: 19:25 | E25: 4 | F25: TLB | G25: SHORT | H25: Variation | I25: 7306 | J25: 7323.25 | K25: 7305.75 | L25: 17.2 | M25: 7297.38 | N25: 0.5 | Q25: YES | R25: YES | T25: 12.75 | U25: 11.75 | V25: 3.04 | W25: STOP_HIT | X25: WIN | Y25: 45.6 | Z25: 0.18 | AA25: 1
A26: 45 | B26: 2026-06-11 | C26: 12:30 | D26: 19:30 | E26: 4 | F26: HFE | G26: SHORT | H26: Variation | I26: 7297.75 | J26: 7323.25 | K26: 7297.5 | L26: 25.5 | M26: 7287.55 | N26: 0.4 | Q26: YES | R26: YES | T26: 25.75 | U26: 48.75 | V26: 3.57 | W26: STOP_HIT | X26: WIN | Y26: 53.5 | Z26: 0.14 | AA26: 11 | AB26: RISK 26pt
A27: 46 | B27: 2026-06-11 | C27: 12:45 | D27: 19:45 | E27: 4 | F27: HFE | G27: SHORT | H27: Variation | I27: 7305.5 | J27: 7323.25 | K27: 7305.25 | L27: 17.8 | M27: 7296.27 | N27: 0.52 | Q27: YES | R27: YES | T27: 33.5 | U27: 41 | V27: 3.24 | W27: STOP_HIT | X27: WIN | Y27: 48.65 | Z27: 0.18 | AA27: 8
A28: 47 | B28: 2026-06-11 | C28: 12:50 | D28: 19:50 | E28: 4 | F28: HFE | G28: SHORT | H28: Variation | I28: 7302.5 | J28: 7323.25 | K28: 7302.25 | L28: 20.8 | M28: 7294.2 | N28: 0.4 | Q28: YES | R28: YES | T28: 30.5 | U28: 44 | V28: 2.93 | W28: STOP_HIT | X28: WIN | Y28: 44 | Z28: 0.14 | AA28: 7
A29: 48 | B29: 2026-06-11 | C29: 12:55 | D29: 19:55 | E29: 4 | F29: HFE | G29: SHORT | H29: Variation | I29: 7290.5 | J29: 7323.25 | K29: 7290.25 | L29: 32.8 | M29: 7277.4 | N29: 0.4 | Q29: YES | R29: YES | T29: 15.5 | U29: 1.5 | V29: 4.53 | W29: STOP_HIT | X29: WIN | Y29: 68 | Z29: 0.14 | AA29: 1 | AB29: RISK 33pt
A30: 49 | B30: 2026-06-11 | C30: 13:00 | D30: 20:00 | E30: 4 | F30: HFE | G30: SHORT | H30: Variation | I30: 7284.25 | J30: 7323.25 | K30: 7323.25 | L30: 39 | M30: 7268.65 | N30: 0.4 | T30: 12.25 | U30: 62.25 | V30: -39 | W30: STOP_HIT | X30: LOSS | Y30: -585 | Z30: -1 | AA30: 5 | AB30: RISK 39pt
A31: 50 | B31: 2026-06-11 | C31: 13:10 | D31: 20:10 | E31: 4 | F31: TLB | G31: LONG | H31: Variation | I31: 7287.5 | J31: 7274.25 | K31: 7274.25 | L31: 13.2 | M31: 7296.11 | N31: 0.65 | T31: 0 | U31: 14 | V31: -13.25 | W31: STOP_HIT | X31: LOSS | Y31: -198.75 | Z31: -1 | AA31: 1
A32: 51 | B32: 2026-06-11 | C32: 13:40 | D32: 20:40 | E32: 4 | F32: TLB | G32: SHORT | H32: Variation | I32: 7362.25 | J32: 7372.25 | K32: 7372.25 | L32: 10 | M32: 7354.75 | N32: 0.75 | T32: 0 | U32: 23.25 | V32: -10 | W32: STOP_HIT | X32: LOSS | Y32: -150 | Z32: -1 | AA32: 1
A33: 52 | B33: 2026-06-11 | C33: 13:45 | D33: 20:45 | E33: 4 | F33: HFE | G33: SHORT | H33: Variation | I33: 7382.75 | J33: 7387.25 | K33: 7382.5 | L33: 4.5 | M33: 7379.15 | N33: 0.8 | Q33: YES | R33: YES | T33: 37.5 | U33: 0.5 | V33: 1.37 | W33: STOP_HIT | X33: WIN | Y33: 20.5 | Z33: 0.3 | AA33: 13
A34: 53 | B34: 2026-06-11 | C34: 13:50 | D34: 20:50 | E34: 4 | F34: TLB | G34: SHORT | H34: Variation | I34: 7367.75 | J34: 7387.25 | K34: 7367.5 | L34: 19.5 | M34: 7358 | N34: 0.5 | Q34: YES | R34: YES | T34: 10.25 | U34: 3.5 | V34: 3.42 | W34: STOP_HIT | X34: WIN | Y34: 51.25 | Z34: 0.18 | AA34: 1
A35: 54 | B35: 2026-06-11 | C35: 13:55 | D35: 20:55 | E35: 4 | F35: TLB | G35: SHORT | H35: Variation | I35: 7362.75 | J35: 7387.25 | K35: 7362.5 | L35: 24.5 | M35: 7352.95 | N35: 0.4 | Q35: YES | R35: YES | T35: 15.25 | U35: 13.75 | V35: 3.43 | W35: STOP_HIT | X35: WIN | Y35: 51.5 | Z35: 0.14 | AA35: 1
A36: 55 | B36: 2026-06-11 | C36: 14:00 | D36: 21:00 | E36: 4 | F36: HFE | G36: SHORT | H36: Variation | I36: 7369.5 | J36: 7387.25 | K36: 7369.25 | L36: 17.8 | M36: 7360.27 | N36: 0.52 | Q36: YES | R36: YES | T36: 24.25 | U36: 8.25 | V36: 3.24 | W36: STOP_HIT | X36: WIN | Y36: 48.65 | Z36: 0.18 | AA36: 3
A37: 56 | B37: 2026-06-11 | C37: 14:05 | D37: 21:05 | E37: 4 | F37: HFE | G37: SHORT | H37: Variation | I37: 7352 | J37: 7387.25 | K37: 7387.25 | L37: 35.2 | M37: 7337.9 | N37: 0.4 | T37: 1.25 | U37: 40.75 | V37: -35.25 | W37: STOP_HIT | X37: LOSS | Y37: -528.75 | Z37: -1 | AA37: 13 | AB37: RISK 35pt
A38: 57 | B38: 2026-06-11 | C38: 14:10 | D38: 21:10 | E38: 4 | F38: HFE | G38: SHORT | H38: Variation | I38: 7353 | J38: 7387.25 | K38: 7387.25 | L38: 34.2 | M38: 7339.3 | N38: 0.4 | T38: 0 | U38: 39.75 | V38: -34.25 | W38: STOP_HIT | X38: LOSS | Y38: -513.75 | Z38: -1 | AA38: 12 | AB38: RISK 34pt
A39: 58 | B39: 2026-06-11 | C39: 14:20 | D39: 21:20 | E39: 4 | F39: ZLR | G39: LONG | H39: Variation | I39: 7375 | J39: 7344.5 | K39: 7375.25 | L39: 30.5 | M39: 7387.2 | N39: 0.4 | Q39: YES | R39: YES | T39: 44.75 | U39: 14.5 | V39: 20.57 | W39: TIME_STOP | X39: WIN | Y39: 308.5 | Z39: 0.67 | AA39: 18 | AB39: RISK 30pt
A40: 59 | B40: 2026-06-11 | C40: 14:25 | D40: 21:25 | E40: 4 | F40: HFE | G40: SHORT | H40: Variation | I40: 7365.25 | J40: 7387.25 | K40: 7387.25 | L40: 22 | M40: 7356.45 | N40: 0.4 | T40: 4.75 | U40: 27.5 | V40: -22 | W40: STOP_HIT | X40: LOSS | Y40: -330 | Z40: -1 | AA40: 9
...

Sheet Summary
A1: MEMS26 — Summary (auto)
A3: Total | B3: =COUNTA(Trades!A2:A53) -> 52
A4: Wins | B4: =COUNTIF(Trades!Y2:Y53,">0") -> 33
A5: Losses | B5: =COUNTIF(Trades!Y2:Y53,"<0") -> 17
A6: Win % | B6: =B3/(B3+B4) -> 0.61176471
A7: Net $ | B7: =SUM(Trades!Y2:Y53) -> -1196.59
A8: Profit factor | B8: =SUMIF(Trades!Y2:Y53,">0")/ABS(SUMIF(Trades!Y2:Y53,"<0")) -> 0.75148702
A9: Avg risk pts | B9: =AVERAGE(Trades!L2:L53) -> 20.857692
A10: Net $ 06-12 only | B10: =SUMIFS(Trades!Y2:Y53,Trades!B2:B53,"2026-06-12") -> -260.62

Sheet ByPattern
A1: Pattern | B1: N | C1: Wins | D1: Losses | E1: Win % | F1: Net $
A2: BEAR_FLAG_SHORT | B2: =COUNTIF(Trades!F:F,A2) -> 2 | C2: =COUNTIFS(Trades!F:F,A2,Trades!Y:Y,">0") -> 1 | D2: =COUNTIFS(Trades!F:F,A2,Trades!Y:Y,"<0") -> 0 | E2: =IF(B2=0,0,C2/B2) -> 0.5 | F2: =SUMIF(Trades!F:F,A2,Trades!Y:Y) -> 230
A3: GB100 | B3: =COUNTIF(Trades!F:F,A3) -> 1 | C3: =COUNTIFS(Trades!F:F,A3,Trades!Y:Y,">0") -> 1 | D3: =COUNTIFS(Trades!F:F,A3,Trades!Y:Y,"<0") -> 0 | E3: =IF(B3=0,0,C3/B3) -> 1 | F3: =SUMIF(Trades!F:F,A3,Trades!Y:Y) -> 99.5
A4: GHOST | B4: =COUNTIF(Trades!F:F,A4) -> 1 | C4: =COUNTIFS(Trades!F:F,A4,Trades!Y:Y,">0") -> 1 | D4: =COUNTIFS(Trades!F:F,A4,Trades!Y:Y,"<0") -> 0 | E4: =IF(B4=0,0,C4/B4) -> 1 | F4: =SUMIF(Trades!F:F,A4,Trades!Y:Y) -> 19.05
A5: HFE | B5: =COUNTIF(Trades!F:F,A5) -> 13 | C5: =COUNTIFS(Trades!F:F,A5,Trades!Y:Y,">0") -> 6 | D5: =COUNTIFS(Trades!F:F,A5,Trades!Y:Y,"<0") -> 7 | E5: =IF(B5=0,0,C5/B5) -> 0.46153846 | F5: =SUMIF(Trades!F:F,A5,Trades!Y:Y) -> -1745.45
A6: HTLB | B6: =COUNTIF(Trades!F:F,A6) -> 2 | C6: =COUNTIFS(Trades!F:F,A6,Trades!Y:Y,">0") -> 2 | D6: =COUNTIFS(Trades!F:F,A6,Trades!Y:Y,"<0") -> 0 | E6: =IF(B6=0,0,C6/B6) -> 1 | F6: =SUMIF(Trades!F:F,A6,Trades!Y:Y) -> 602.5
A7: INITIATIVE_LONG | B7: =COUNTIF(Trades!F:F,A7) -> 1 | C7: =COUNTIFS(Trades!F:F,A7,Trades!Y:Y,">0") -> 1 | D7: =COUNTIFS(Trades!F:F,A7,Trades!Y:Y,"<0") -> 0 | E7: =IF(B7=0,0,C7/B7) -> 1 | F7: =SUMIF(Trades!F:F,A7,Trades!Y:Y) -> 25
A8: INITIATIVE_SHORT | B8: =COUNTIF(Trades!F:F,A8) -> 2 | C8: =COUNTIFS(Trades!F:F,A8,Trades!Y:Y,">0") -> 1 | D8: =COUNTIFS(Trades!F:F,A8,Trades!Y:Y,"<0") -> 0 | E8: =IF(B8=0,0,C8/B8) -> 0.5 | F8: =SUMIF(Trades!F:F,A8,Trades!Y:Y) -> 39.05
A9: REACTIVE_LONG | B9: =COUNTIF(Trades!F:F,A9) -> 1 | C9: =COUNTIFS(Trades!F:F,A9,Trades!Y:Y,">0") -> 0 | D9: =COUNTIFS(Trades!F:F,A9,Trades!Y:Y,"<0") -> 1 | E9: =IF(B9=0,0,C9/B9) -> 0 | F9: =SUMIF(Trades!F:F,A9,Trades!Y:Y) -> -337.5
A10: REACTIVE_SHORT | B10: =COUNTIF(Trades!F:F,A10) -> 2 | C10: =COUNTIFS(Trades!F:F,A10,Trades!Y:Y,">0") -> 2 | D10: =COUNTIFS(Trades!F:F,A10,Trades!Y:Y,"<0") -> 0 | E10: =IF(B10=0,0,C10/B10) -> 1 | F10: =SUMIF(Trades!F:F,A10,Trades!Y:Y) -> 136.38
A11: TLB | B11: =COUNTIF(Trades!F:F,A11) -> 15 | C11: =COUNTIFS(Trades!F:F,A11,Trades!Y:Y,">0") -> 11 | D11: =COUNTIFS(Trades!F:F,A11,Trades!Y:Y,"<0") -> 4 | E11: =IF(B11=0,0,C11/B11) -> 0.73333333 | F11: =SUMIF(Trades!F:F,A11,Trades!Y:Y) -> 632.53
A12: ZLR | B12: =COUNTIF(Trades!F:F,A12) -> 12 | C12: =COUNTIFS(Trades!F:F,A12,Trades!Y:Y,">0") -> 7 | D12: =COUNTIFS(Trades!F:F,A12,Trades!Y:Y,"<0") -> 5 | E12: =IF(B12=0,0,C12/B12) -> 0.58333333 | F12: =SUMIF(Trades!F:F,A12,Trades!Y:Y) -> -897.65

Sheet DecisionRules
A1: איך המערכת קובעת — חוקי ההחלטה (מקור: config/stop_anchors.yaml + targets.yaml + trade_manager)
A2: שלב | B2: חוק
A3: כמות חוזים | B3: לפי סיכון: עד 15 נק׳=3 חוזים · עד 25=2 · מעל 25=1. תקרה: אסטרטגית 3 / טקטית 2. הסופי = הזהיר מבין השלושה.
A4: תקרת סיכון | B4: 25 נק׳ לחוזה ($125). שערי pre_fire: מינ׳ 2 נק׳ / מקס׳ 60 נק׳ (דגלים, פעילים מהיום).
A5: סטופ — עיקרון | B5: עוגן מבני פר-תבנית + 3 טיקים מעבר לקצה. הסטופ המבני תמיד גובר; ATR לא מזיז אותו. רצפה 4 טיקים.
A6: עוגן סטופ פר-תבנית
A7: תבנית | B7: עוגן
A8: ZLR (S4 המשך) | B8: נמוך/גבוה אשכול — 4 ברים אחורה
A9: TLB (S4 המשך) | B9: מאז פסגת קו-המגמה — עד 8 ברים
A10: TT (S4 המשך) | B10: יציאת ZL — עד 9 ברים
A11: VEGAS (S4 היפוך) | B11: קיצון סווינג · T1×0.75 · T2×1.0 (measured)
A12: GHOST (S4 היפוך) | B12: כתף · T1 cap 0.5×measured
A13: HTLB (S4 היפוך) | B13: קיצון הקונסולידציה (לא בר-הפריצה)
A14: HFE (S4 היפוך) | B14: בר-הקיצון של CCI ±200 · סולם T1 מדרגה מטה (התבנית החלשה). ⚠️ כש-CCI נשאר בקיצון — אותו עוגן משותף לכמה כניסות (הבעיה של היום).
A15: Reactive (S2) | B15: אזור תמיכה/התנגדות — 4 ברים
A16: Initiative/Flag (S2) | B16: בר-הפריצה (הדוק בכוונה)
A17: Double B/T (S2) | B17: התחתית/פסגה השנייה
A18: HnS (S2) | B18: הכתף הימנית (לא ה-neckline)
A19: יעדים
A20: רכיב | B20: חוק
A21: T1 — סולם לפי סיכון | B21: עד 5 נק׳→1.0R · עד 10→0.75R · עד 15→0.65R · עד 20→0.5R · עד 25→0.4R. תבניות היפוך ×0.8. רצפת T1: 3 נק׳. HFE: מדרגה אחת מטה.
A22: T2/T3 — S4 | B22: אין (None) — אופציה 1: מנגנון חציית-CCI (סע׳ 1.6) נדחה ולא מומש. לכן ב-S4 פגיעת T2 בלתי-אפשרית מבנית.
A23: T2 — S2 | B23: לפי day_type targets: ‎2.0R (המשך) / ‎1.5R (היפוך) מהכניסה.
A24: BE אחרי T1 | B24: בפגיעת T1: סטופ זז ל-כניסה+טיק (SMART_BE). הראנר נשאר בלי יעד ובלי trail — יוצא ב-BE / TIME_STOP / סיגנל נגדי.
A25: TIME_STOP | B25: ‎90 דק׳ קבוע בקוד (S4). הערכים פר-day_type ב-targets.yaml לא נצרכים — באג ידוע (FIX 5).
A26: נר ענק (>25 נק׳) | B26: חוזה 1 · יעד = הקרוב מבין 1R / רמה מבנית / 50-75% מהטווח שנותר · BE אחרי 15 נק׳ · spike ראשון בלבד.
A27: שערים וקירור
A28: שער | B28: חוק
A29: pre_fire R:R | B29: ‎R:R≥1.0 על הראנר (T2; אם T2=None — מכפיל צפוי 2.0/1.5R). תוקן 06-11 — לפני כן נמדד על T1 וחסם הכול.
A30: קירור 2-סטופים (ζ.A4) | B30: 2 יציאות STOP רצופות → חסימה 30 דק׳ — גלובלי, לא פר-תבנית (לכן לא עצר את ה-HFE היום).
A31: שומר אשכול (ζ.A5) | B31: 5 עסקאות ב-60 שניות → חסימה 5 דק׳.
A32: אין (פערים) | B32: אין קירור פר-תבנית+כיוון אחרי סטופ · אין מפסק הפסדים-רצופים פר-תבנית · אין trail לראנר — שלושת הפערים המרכזיים שזוהו היום.

Sheet MgmtLog
A1: Trade ID | B1: Timestamp | C1: Action | D1: Value
A2: 10 | B2: 2026-06-05 21:33:03.253070+03:00 | C2: T1_HIT | D2: {'ts': '2026-06-05T18:30:00+00:00'}
A3: 10 | B3: 2026-06-05 21:33:03.254030+03:00 | C3: SMART_BE | D3: {'to': 7443.75, 'from': 7457.03125}
A4: 10 | B4: 2026-06-05 21:47:19.252714+03:00 | C4: T2_HIT | D4: {'ts': '2026-06-05T18:45:00+00:00'}
A5: 10 | B5: 2026-06-08 14:15:02.666142+03:00 | C5: STOP_HIT | D5: {'ts': '2026-06-08T11:10:00+00:00', 'stop': 7443.75}
A6: 12 | B6: 2026-06-05 21:20:01.281074+03:00 | C6: T1_HIT | D6: {'ts': '2026-06-05T18:20:00+00:00'}
A7: 12 | B7: 2026-06-05 21:20:01.306513+03:00 | C7: SMART_BE | D7: {'to': 7443.5, 'from': 7447.25}
A8: 12 | B8: 2026-06-05 21:20:53.448825+03:00 | C8: STOP_HIT | D8: {'ts': '2026-06-05T18:20:00+00:00', 'stop': 7443.5}
A9: 13 | B9: 2026-06-05 22:10:02.450515+03:00 | C9: T1_HIT | D9: {'ts': '2026-06-05T19:10:00+00:00'}
A10: 13 | B10: 2026-06-05 22:10:02.450622+03:00 | C10: SMART_BE | D10: {'to': 7414.0, 'from': 7418.0}
A11: 13 | B11: 2026-06-05 22:10:02.456305+03:00 | C11: T2_HIT | D11: {'ts': '2026-06-05T19:10:00+00:00'}
A12: 13 | B12: 2026-06-08 11:03:06.921549+03:00 | C12: STOP_HIT | D12: {'ts': '2026-06-08T08:00:00+00:00', 'stop': 7414.0}
A13: 20 | B13: 2026-06-09 16:55:02.925093+03:00 | C13: T1_HIT | D13: {'ts': '2026-06-09T13:55:00+00:00'}
... A120: 73 | B120: 2026-06-12 18:52:57.390794+03:00 | C120: STOP_HIT | D120: {'ts': '2026-06-12T15:50:00+00:00', 'stop': 7426.25}
